Workbook

Sheet Employee_Data
A1: Emp_ID | B1: Full_Name | C1: Gender | D1: Department | E1: Position_Level | F1: Employment_Type | G1: Join_Date | H1: Age | I1: Education | J1: Region | K1: Salary | L1: Performance_Score | M1: Tenure_Years | N1: Status
A2: EMP0001 | B2: Budi Kusuma | C2: Male | D2: Marketing | E2: Junior | F2: Full-Time | G2: 2016-11-24 | H2: 56 | I2: Diploma | J2: Medan | K2: 5447674 | L2: 2.7 | M2: 8 | N2: Active
A3: EMP0002 | B3: Bagas Utama | C3: Male | D3: Legal | E3: Junior | F3: Full-Time | G3: 2019-01-25 | H3: 32 | I3: Master | J3: Bandung | K3: 5816807 | L3: 3 | M3: 5 | N3: Active
A4: EMP0003 | B4: Andi Hidayat | C4: Male | D4: Finance | E4: Senior | F4: Part-Time | G4: 2019-01-24 | H4: 51 | I4: Bachelor | J4: Medan | K4: 8277300 | L4: 3.2 | M4: 5 | N4: Active
A5: EMP0004 | B5: Dina Utama | C5: Female | D5: Finance | E5: Staff | F5: Full-Time | G5: 2019-02-28 | H5: 36 | I5: Master | J5: Medan | K5: 4362720 | L5: 4.1 | M5: 5 | N5: Active
A6: EMP0005 | B6: Ayu Utama | C6: Female | D6: IT | E6: Director | F6: Contract | G6: 2016-10-21 | H6: 32 | I6: Bachelor | J6: Surabaya | K6: 26343817 | L6: 3.4 | M6: 8 | N6: Inactive
A7: EMP0006 | B7: Hendra Santoso | C7: Male | D7: Marketing | E7: Staff | F7: Part-Time | G7: 2021-05-03 | H7: 35 | I7: PhD | J7: Bali | K7: 5035913 | L7: 3.3 | M7: 3 | N7: Active
A8: EMP0007 | B8: Maya Pratama | C8: Female | D8: IT | E8: Junior | F8: Full-Time | G8: 2023-09-09 | H8: 49 | I8: Master | J8: Medan | K8: 5942994 | L8: 5 | M8: 1 | N8: Active
A9: EMP0008 | B9: Dewi Santoso | C9: Female | D9: Finance | E9: Junior | F9: Full-Time | G9: 2021-10-03 | H9: 46 | I9: Bachelor | J9: Medan | K9: 6193671 | L9: 4.9 | M9: 3 | N9: Active
A10: EMP0009 | B10: Andi Kusuma | C10: Male | D10: Sales | E10: Staff | F10: Full-Time | G10: 2017-08-01 | H10: 38 | I10: PhD | J10: Semarang | K10: 4250983 | L10: 4.8 | M10: 7 | N10: Active
A11: EMP0010 | B11: Wulan Utama | C11: Female | D11: HR | E11: Senior | F11: Part-Time | G11: 2023-09-01 | H11: 42 | I11: Bachelor | J11: Jakarta | K11: 10190471 | L11: 4.7 | M11: 1 | N11: Active
A12: EMP0011 | B12: Lina Santoso | C12: Female | D12: Marketing | E12: Manager | F12: Contract | G12: 2016-12-16 | H12: 26 | I12: PhD | J12: Bali | K12: 19646254 | L12: 2.8 | M12: 8 | N12: Active
A13: EMP0012 | B13: Dimas Hidayat | C13: Male | D13: Marketing | E13: Manager | F13: Part-Time | G13: 2018-12-10 | H13: 47 | I13: PhD | J13: Makassar | K13: 17880392 | L13: 4.7 | M13: 6 | N13: Active
... A201: EMP0200 | B201: Rizki Wijaya | C201: Male | D201: Legal | E201: Senior | F201: Contract | G201: 2020-03-08 | H201: 39 | I201: Bachelor | J201: Surabaya | K201: 9345142 | L201: 4 | M201: 4 | N201: Active

Sheet Summary_KPI
A1: HUMAN CAPITAL ANALYTICS | WORKFORCE DASHBOARD
A3: 👥 TOTAL EMPLOYEES | C3: ✅ ACTIVE EMPLOYEES | E3: 📅 AVG AGE | G3: 🏅 AVG TENURE (YRS) | I3: 💰 AVG SALARY (IDR) | K3: ⭐ AVG PERFORMANCE
A4: =COUNTA(Employee_Data!A2:A201) | C4: =COUNTIF(Employee_Data!N2:N201,"Active") | E4: =ROUND(AVERAGE(Employee_Data!H2:H201),1) | G4: =ROUND(AVERAGE(Employee_Data!M2:M201),1) | I4: =ROUND(AVERAGE(Employee_Data!K2:K201),0) | K4: =ROUND(AVERAGE(Employee_Data!L2:L201),2)
A9: WORKFORCE BY DEPARTMENT | H9: GENDER DISTRIBUTION
A10: Department | B10: Total | C10: Active | D10: % Active | E10: Avg Salary | F10: Avg Performance | H10: Gender | I10: Count | J10: % Share | K10: Trend
A11: Operations | B11: =COUNTIF(Employee_Data!D:D,A11) | C11: =COUNTIFS(Employee_Data!D:D,A11,Employee_Data!N:N,"Active") | D11: =IF(B11=0,0,C11/B11) | E11: =AVERAGEIF(Employee_Data!D:D,A11,Employee_Data!K:K) | F11: =AVERAGEIF(Employee_Data!D:D,A11,Employee_Data!L:L) | H11: Male | I11: =COUNTIF(Employee_Data!C:C,H11) | J11: =IF(COUNTA(Employee_Data!C2:C201)=0,0,I11/COUNTA(Employee_Data!C2:C201)) | K11: ▬▬▬▬▬
A12: Finance | B12: =COUNTIF(Employee_Data!D:D,A12) | C12: =COUNTIFS(Employee_Data!D:D,A12,Employee_Data!N:N,"Active") | D12: =IF(B12=0,0,C12/B12) | E12: =AVERAGEIF(Employee_Data!D:D,A12,Employee_Data!K:K) | F12: =AVERAGEIF(Employee_Data!D:D,A12,Employee_Data!L:L) | H12: Female | I12: =COUNTIF(Employee_Data!C:C,H12) | J12: =IF(COUNTA(Employee_Data!C2:C201)=0,0,I12/COUNTA(Employee_Data!C2:C201)) | K12: ▬▬▬
A13: HR | B13: =COUNTIF(Employee_Data!D:D,A13) | C13: =COUNTIFS(Employee_Data!D:D,A13,Employee_Data!N:N,"Active") | D13: =IF(B13=0,0,C13/B13) | E13: =AVERAGEIF(Employee_Data!D:D,A13,Employee_Data!K:K) | F13: =AVERAGEIF(Employee_Data!D:D,A13,Employee_Data!L:L)
A14: Marketing | B14: =COUNTIF(Employee_Data!D:D,A14) | C14: =COUNTIFS(Employee_Data!D:D,A14,Employee_Data!N:N,"Active") | D14: =IF(B14=0,0,C14/B14) | E14: =AVERAGEIF(Employee_Data!D:D,A14,Employee_Data!K:K) | F14: =AVERAGEIF(Employee_Data!D:D,A14,Employee_Data!L:L)
A15: IT | B15: =COUNTIF(Employee_Data!D:D,A15) | C15: =COUNTIFS(Employee_Data!D:D,A15,Employee_Data!N:N,"Active") | D15: =IF(B15=0,0,C15/B15) | E15: =AVERAGEIF(Employee_Data!D:D,A15,Employee_Data!K:K) | F15: =AVERAGEIF(Employee_Data!D:D,A15,Employee_Data!L:L) | H15: EDUCATION DISTRIBUTION
A16: Sales | B16: =COUNTIF(Employee_Data!D:D,A16) | C16: =COUNTIFS(Employee_Data!D:D,A16,Employee_Data!N:N,"Active") | D16: =IF(B16=0,0,C16/B16) | E16: =AVERAGEIF(Employee_Data!D:D,A16,Employee_Data!K:K) | F16: =AVERAGEIF(Employee_Data!D:D,A16,Employee_Data!L:L) | H16: Education | I16: Count | J16: % Share
A17: Legal | B17: =COUNTIF(Employee_Data!D:D,A17) | C17: =COUNTIFS(Employee_Data!D:D,A17,Employee_Data!N:N,"Active") | D17: =IF(B17=0,0,C17/B17) | E17: =AVERAGEIF(Employee_Data!D:D,A17,Employee_Data!K:K) | F17: =AVERAGEIF(Employee_Data!D:D,A17,Employee_Data!L:L) | H17: High School | I17: =COUNTIF(Employee_Data!I:I,H17) | J17: =IF(COUNTA(Employee_Data!I2:I201)=0,0,I17/COUNTA(Employee_Data!I2:I201))
A18: R&D | B18: =COUNTIF(Employee_Data!D:D,A18) | C18: =COUNTIFS(Employee_Data!D:D,A18,Employee_Data!N:N,"Active") | D18: =IF(B18=0,0,C18/B18) | E18: =AVERAGEIF(Employee_Data!D:D,A18,Employee_Data!K:K) | F18: =AVERAGEIF(Employee_Data!D:D,A18,Employee_Data!L:L) | H18: Diploma | I18: =COUNTIF(Employee_Data!I:I,H18) | J18: =IF(COUNTA(Employee_Data!I2:I201)=0,0,I18/COUNTA(Employee_Data!I2:I201))
A19: TOTAL / AVERAGE | B19: =SUM(B11:B18) | C19: =SUM(C11:C18) | D19: =IF(B19=0,0,C19/B19) | E19: =AVERAGE(E11:E18) | F19: =AVERAGE(F11:F18) | H19: Bachelor | I19: =COUNTIF(Employee_Data!I:I,H19) | J19: =IF(COUNTA(Employee_Data!I2:I201)=0,0,I19/COUNTA(Employee_Data!I2:I201))
H20: Master | I20: =COUNTIF(Employee_Data!I:I,H20) | J20: =IF(COUNTA(Employee_Data!I2:I201)=0,0,I20/COUNTA(Employee_Data!I2:I201))
H21: PhD | I21: =COUNTIF(Employee_Data!I:I,H21) | J21: =IF(COUNTA(Employee_Data!I2:I201)=0,0,I21/COUNTA(Employee_Data!I2:I201))

Sheet Headcount_Trend
A1: HEADCOUNT TREND ANALYSIS | 2015 – 2024
A3: Year | B3: Total Headcount | C3: New Hires | D3: Attrition | E3: Net Growth | F3: Growth Rate %
A4: 2015 | B4: 82 | C4: 18 | D4: 5 | E4: =C4-D4 | F4: —
A5: 2016 | B5: 95 | C5: 22 | D5: 9 | E5: =C5-D5 | F5: =IF(B4=0,0,(B5-B4)/B4)
A6: 2017 | B6: 110 | C6: 26 | D6: 11 | E6: =C6-D6 | F6: =IF(B5=0,0,(B6-B5)/B5)
A7: 2018 | B7: 128 | C7: 28 | D7: 11 | E7: =C7-D7 | F7: =IF(B6=0,0,(B7-B6)/B6)
A8: 2019 | B8: 145 | C8: 25 | D8: 8 | E8: =C8-D8 | F8: =IF(B7=0,0,(B8-B7)/B7)
A9: 2020 | B9: 158 | C9: 20 | D9: 7 | E9: =C9-D9 | F9: =IF(B8=0,0,(B9-B8)/B8)
A10: 2021 | B10: 170 | C10: 18 | D10: 6 | E10: =C10-D10 | F10: =IF(B9=0,0,(B10-B9)/B9)
A11: 2022 | B11: 182 | C11: 20 | D11: 8 | E11: =C11-D11 | F11: =IF(B10=0,0,(B11-B10)/B10)
A12: 2023 | B12: 193 | C12: 17 | D12: 6 | E12: =C12-D12 | F12: =IF(B11=0,0,(B12-B11)/B11)
A13: 2024 | B13: 200 | C13: 15 | D13: 8 | E13: =C13-D13 | F13: =IF(B12=0,0,(B13-B12)/B12)

Sheet Regional_Distribution
A1: WORKFORCE DISTRIBUTION BY REGION
A3: Region | B3: Total | C3: Male | D3: Female | E3: F-T | F3: P-T | G3: Contract | H3: Avg Salary | I3: % of Total
A4: Jakarta | B4: =COUNTIF(Employee_Data!J:J,A4) | C4: =COUNTIFS(Employee_Data!J:J,A4,Employee_Data!C:C,"Male") | D4: =COUNTIFS(Employee_Data!J:J,A4,Employee_Data!C:C,"Female") | E4: =COUNTIFS(Employee_Data!J:J,A4,Employee_Data!F:F,"Full-Time") | F4: =COUNTIFS(Employee_Data!J:J,A4,Employee_Data!F:F,"Part-Time") | G4: =COUNTIFS(Employee_Data!J:J,A4,Employee_Data!F:F,"Contract") | H4: =AVERAGEIF(Employee_Data!J:J,A4,Employee_Data!K:K) | I4: =IF(COUNTA(Employee_Data!J2:J201)=0,0,B4/COUNTA(Employee_Data!J2:J201))
A5: Surabaya | B5: =COUNTIF(Employee_Data!J:J,A5) | C5: =COUNTIFS(Employee_Data!J:J,A5,Employee_Data!C:C,"Male") | D5: =COUNTIFS(Employee_Data!J:J,A5,Employee_Data!C:C,"Female") | E5: =COUNTIFS(Employee_Data!J:J,A5,Employee_Data!F:F,"Full-Time") | F5: =COUNTIFS(Employee_Data!J:J,A5,Employee_Data!F:F,"Part-Time") | G5: =COUNTIFS(Employee_Data!J:J,A5,Employee_Data!F:F,"Contract") | H5: =AVERAGEIF(Employee_Data!J:J,A5,Employee_Data!K:K) | I5: =IF(COUNTA(Employee_Data!J2:J201)=0,0,B5/COUNTA(Employee_Data!J2:J201))
A6: Bandung | B6: =COUNTIF(Employee_Data!J:J,A6) | C6: =COUNTIFS(Employee_Data!J:J,A6,Employee_Data!C:C,"Male") | D6: =COUNTIFS(Employee_Data!J:J,A6,Employee_Data!C:C,"Female") | E6: =COUNTIFS(Employee_Data!J:J,A6,Employee_Data!F:F,"Full-Time") | F6: =COUNTIFS(Employee_Data!J:J,A6,Employee_Data!F:F,"Part-Time") | G6: =COUNTIFS(Employee_Data!J:J,A6,Employee_Data!F:F,"Contract") | H6: =AVERAGEIF(Employee_Data!J:J,A6,Employee_Data!K:K) | I6: =IF(COUNTA(Employee_Data!J2:J201)=0,0,B6/COUNTA(Employee_Data!J2:J201))
A7: Medan | B7: =COUNTIF(Employee_Data!J:J,A7) | C7: =COUNTIFS(Employee_Data!J:J,A7,Employee_Data!C:C,"Male") | D7: =COUNTIFS(Employee_Data!J:J,A7,Employee_Data!C:C,"Female") | E7: =COUNTIFS(Employee_Data!J:J,A7,Employee_Data!F:F,"Full-Time") | F7: =COUNTIFS(Employee_Data!J:J,A7,Employee_Data!F:F,"Part-Time") | G7: =COUNTIFS(Employee_Data!J:J,A7,Employee_Data!F:F,"Contract") | H7: =AVERAGEIF(Employee_Data!J:J,A7,Employee_Data!K:K) | I7: =IF(COUNTA(Employee_Data!J2:J201)=0,0,B7/COUNTA(Employee_Data!J2:J201))
A8: Bali | B8: =COUNTIF(Employee_Data!J:J,A8) | C8: =COUNTIFS(Employee_Data!J:J,A8,Employee_Data!C:C,"Male") | D8: =COUNTIFS(Employee_Data!J:J,A8,Employee_Data!C:C,"Female") | E8: =COUNTIFS(Employee_Data!J:J,A8,Employee_Data!F:F,"Full-Time") | F8: =COUNTIFS(Employee_Data!J:J,A8,Employee_Data!F:F,"Part-Time") | G8: =COUNTIFS(Employee_Data!J:J,A8,Employee_Data!F:F,"Contract") | H8: =AVERAGEIF(Employee_Data!J:J,A8,Employee_Data!K:K) | I8: =IF(COUNTA(Employee_Data!J2:J201)=0,0,B8/COUNTA(Employee_Data!J2:J201))
A9: Makassar | B9: =COUNTIF(Employee_Data!J:J,A9) | C9: =COUNTIFS(Employee_Data!J:J,A9,Employee_Data!C:C,"Male") | D9: =COUNTIFS(Employee_Data!J:J,A9,Employee_Data!C:C,"Female") | E9: =COUNTIFS(Employee_Data!J:J,A9,Employee_Data!F:F,"Full-Time") | F9: =COUNTIFS(Employee_Data!J:J,A9,Employee_Data!F:F,"Part-Time") | G9: =COUNTIFS(Employee_Data!J:J,A9,Employee_Data!F:F,"Contract") | H9: =AVERAGEIF(Employee_Data!J:J,A9,Employee_Data!K:K) | I9: =IF(COUNTA(Employee_Data!J2:J201)=0,0,B9/COUNTA(Employee_Data!J2:J201))
A10: Semarang | B10: =COUNTIF(Employee_Data!J:J,A10) | C10: =COUNTIFS(Employee_Data!J:J,A10,Employee_Data!C:C,"Male") | D10: =COUNTIFS(Employee_Data!J:J,A10,Employee_Data!C:C,"Female") | E10: =COUNTIFS(Employee_Data!J:J,A10,Employee_Data!F:F,"Full-Time") | F10: =COUNTIFS(Employee_Data!J:J,A10,Employee_Data!F:F,"Part-Time") | G10: =COUNTIFS(Employee_Data!J:J,A10,Employee_Data!F:F,"Contract") | H10: =AVERAGEIF(Employee_Data!J:J,A10,Employee_Data!K:K) | I10: =IF(COUNTA(Employee_Data!J2:J201)=0,0,B10/COUNTA(Employee_Data!J2:J201))
A11: TOTAL | B11: =SUM(B4:B10) | C11: =SUM(C4:C10) | D11: =SUM(D4:D10) | E11: =SUM(E4:E10) | F11: =SUM(F4:F10) | G11: =SUM(G4:G10) | H11: =SUM(H4:H10)

Sheet Position_Salary
A1: POSITION LEVEL & SALARY ANALYSIS
A3: Position Level | B3: Count | C3: % Share | D3: Min Salary | E3: Max Salary | F3: Avg Salary | G3: Avg Performance | H3: Avg Tenure
A4: Staff | B4: =COUNTIF(Employee_Data!E:E,A4) | C4: =IF(COUNTA(Employee_Data!E2:E201)=0,0,B4/COUNTA(Employee_Data!E2:E201)) | D4: =MINIFS(Employee_Data!K:K,Employee_Data!E:E,A4) | E4: =MAXIFS(Employee_Data!K:K,Employee_Data!E:E,A4) | F4: =AVERAGEIF(Employee_Data!E:E,A4,Employee_Data!K:K) | G4: =AVERAGEIF(Employee_Data!E:E,A4,Employee_Data!L:L) | H4: =AVERAGEIF(Employee_Data!E:E,A4,Employee_Data!M:M)
A5: Junior | B5: =COUNTIF(Employee_Data!E:E,A5) | C5: =IF(COUNTA(Employee_Data!E2:E201)=0,0,B5/COUNTA(Employee_Data!E2:E201)) | D5: =MINIFS(Employee_Data!K:K,Employee_Data!E:E,A5) | E5: =MAXIFS(Employee_Data!K:K,Employee_Data!E:E,A5) | F5: =AVERAGEIF(Employee_Data!E:E,A5,Employee_Data!K:K) | G5: =AVERAGEIF(Employee_Data!E:E,A5,Employee_Data!L:L) | H5: =AVERAGEIF(Employee_Data!E:E,A5,Employee_Data!M:M)
A6: Senior | B6: =COUNTIF(Employee_Data!E:E,A6) | C6: =IF(COUNTA(Employee_Data!E2:E201)=0,0,B6/COUNTA(Employee_Data!E2:E201)) | D6: =MINIFS(Employee_Data!K:K,Employee_Data!E:E,A6) | E6: =MAXIFS(Employee_Data!K:K,Employee_Data!E:E,A6) | F6: =AVERAGEIF(Employee_Data!E:E,A6,Employee_Data!K:K) | G6: =AVERAGEIF(Employee_Data!E:E,A6,Employee_Data!L:L) | H6: =AVERAGEIF(Employee_Data!E:E,A6,Employee_Data!M:M)
A7: Supervisor | B7: =COUNTIF(Employee_Data!E:E,A7) | C7: =IF(COUNTA(Employee_Data!E2:E201)=0,0,B7/COUNTA(Employee_Data!E2:E201)) | D7: =MINIFS(Employee_Data!K:K,Employee_Data!E:E,A7) | E7: =MAXIFS(Employee_Data!K:K,Employee_Data!E:E,A7) | F7: =AVERAGEIF(Employee_Data!E:E,A7,Employee_Data!K:K) | G7: =AVERAGEIF(Employee_Data!E:E,A7,Employee_Data!L:L) | H7: =AVERAGEIF(Employee_Data!E:E,A7,Employee_Data!M:M)
A8: Manager | B8: =COUNTIF(Employee_Data!E:E,A8) | C8: =IF(COUNTA(Employee_Data!E2:E201)=0,0,B8/COUNTA(Employee_Data!E2:E201)) | D8: =MINIFS(Employee_Data!K:K,Employee_Data!E:E,A8) | E8: =MAXIFS(Employee_Data!K:K,Employee_Data!E:E,A8) | F8: =AVERAGEIF(Employee_Data!E:E,A8,Employee_Data!K:K) | G8: =AVERAGEIF(Employee_Data!E:E,A8,Employee_Data!L:L) | H8: =AVERAGEIF(Employee_Data!E:E,A8,Employee_Data!M:M)
A9: Director | B9: =COUNTIF(Employee_Data!E:E,A9) | C9: =IF(COUNTA(Employee_Data!E2:E201)=0,0,B9/COUNTA(Employee_Data!E2:E201)) | D9: =MINIFS(Employee_Data!K:K,Employee_Data!E:E,A9) | E9: =MAXIFS(Employee_Data!K:K,Employee_Data!E:E,A9) | F9: =AVERAGEIF(Employee_Data!E:E,A9,Employee_Data!K:K) | G9: =AVERAGEIF(Employee_Data!E:E,A9,Employee_Data!L:L) | H9: =AVERAGEIF(Employee_Data!E:E,A9,Employee_Data!M:M)
A12: WORKFORCE AGE BRACKET
A13: Age Group | B13: Count | C13: % Share
A14: 20-29 | B14: =COUNTIFS(Employee_Data!H:H,">="&20,Employee_Data!H:H,"<="&29) | C14: =IF(COUNTA(Employee_Data!H2:H201)=0,0,B14/COUNTA(Employee_Data!H2:H201))
A15: 30-39 | B15: =COUNTIFS(Employee_Data!H:H,">="&30,Employee_Data!H:H,"<="&39) | C15: =IF(COUNTA(Employee_Data!H2:H201)=0,0,B15/COUNTA(Employee_Data!H2:H201))
A16: 40-49 | B16: =COUNTIFS(Employee_Data!H:H,">="&40,Employee_Data!H:H,"<="&49) | C16: =IF(COUNTA(Employee_Data!H2:H201)=0,0,B16/COUNTA(Employee_Data!H2:H201))
A17: 50-59 | B17: =COUNTIFS(Employee_Data!H:H,">="&50,Employee_Data!H:H,"<="&59) | C17: =IF(COUNTA(Employee_Data!H2:H201)=0,0,B17/COUNTA(Employee_Data!H2:H201))
A18: 60+ | B18: =COUNTIFS(Employee_Data!H:H,">="&60,Employee_Data!H:H,"<="&99) | C18: =IF(COUNTA(Employee_Data!H2:H201)=0,0,B18/COUNTA(Employee_Data!H2:H201))

Sheet PowerBI_Setup_Guide
A1: STEP-BY-STEP: CONNECT THIS EXCEL TO POWER BI
A3: STEP 1 – INSTALL POWER BI DESKTOP
A4: URL ► | B4: https://powerbi.microsoft.com/en-us/downloads/ → Click 'Download free'
A5: Install | B5: Run the .msi installer → Accept license → Click Install → Launch Power BI Desktop
A6: Sign in | B6: Sign in with your Microsoft / Office 365 account (or create a free account)
A8: STEP 2 – CONNECT THIS EXCEL FILE
A9: Action | B9: Home ribbon → Get Data → Excel Workbook
A10: Browse | B10: Navigate to this file (Human_Capital_Dashboard.xlsx) → Open
A11: Select | B11: In Navigator pane: check Employee_Data Summary_KPI Headcount_Trend Regional_Distribution Position_Salary
A12: Load | B12: Click 'Transform Data' to open Power Query Editor, OR click 'Load' to load directly
A14: STEP 3 – POWER QUERY TRANSFORMATIONS
A15: Join_Date | B15: Select Join_Date column → Transform tab → Data Type → Date
A16: Salary | B16: Select Salary column → Transform → Data Type → Whole Number
A17: Age/Tenure | B17: Select Age & Tenure_Years → Data Type → Whole Number
A18: Filter | B18: Select Status column → Filter Rows → Equals 'Active' (for active-only visuals)
A19: Close | B19: Home → Close & Apply
A21: STEP 4 – BUILD DATA MODEL (Relationships)
A22: Open | B22: Model view (left sidebar icon) → drag Emp_ID from Employee_Data to any lookup table
A23: Tip | B23: All lookup tables should have a 1-to-many relationship with Employee_Data
A25: STEP 5 – CREATE MEASURES (DAX)
A26: Total Emp | B26: Total Employees = COUNTROWS(Employee_Data)
A27: Active | B27: Active Employees = CALCULATE(COUNTROWS(Employee_Data), Employee_Data[Status]="Active")
A28: Attrition | B28: Attrition Rate = DIVIDE([Active Employees], [Total Employees])
A29: Avg Sal | B29: Avg Salary = AVERAGE(Employee_Data[Salary])
A30: Avg Perf | B30: Avg Performance = AVERAGE(Employee_Data[Performance_Score])
A31: Avg Age | B31: Avg Age = AVERAGE(Employee_Data[Age])
A33: STEP 6 – BUILD VISUALS
A34: KPI Cards | B34: Insert → Card visual → drag each Measure into Value field
A35: Bar Chart | B35: Insert → Clustered Bar → Axis = Department, Value = Total Employees
A36: Pie Chart | B36: Insert → Pie Chart → Legend = Gender, Values = Total Employees
A37: Map | B37: Insert → Map or Filled Map → Location = Region, Values = Total Employees
A38: Line Chart | B38: Insert → Line Chart → Axis = Join_Date (year), Values = Total Employees
A39: Table | B39: Insert → Table → Add: Department, Position, Avg Salary, Avg Performance
A40: Slicer | B40: Insert → Slicer → add slicers for: Department / Region / Gender / Year
A42: STEP 7 – FORMAT DASHBOARD
A43: Theme | B43: View tab → Themes → choose 'Executive' or upload custom theme JSON
A44: Colors | B44: Recommended palette: #1F3864 (navy), #2E75B6 (blue), #C9A84C (gold)
A45: Canvas | B45: View → Page view → set to 1280×720 or 1920×1080
A47: STEP 8 – PUBLISH TO POWER BI SERVICE
A48: Publish | B48: Home → Publish → select workspace → wait for upload to complete
...

Sheet Documentation
A1: FIELD GLOSSARY & DATA DICTIONARY
A3: Field Name | B3: Description
A4: Emp_ID | B4: Unique employee identifier — format EMP0001
A5: Full_Name | B5: Employee full name (First + Last)
A6: Gender | B6: Male / Female
A7: Department | B7: Business unit: Operations, Finance, HR, Marketing, IT, Sales, Legal, R&D
A8: Position_Level | B8: Hierarchy: Staff → Junior → Senior → Supervisor → Manager → Director
A9: Employment_Type | B9: Full-Time | Part-Time | Contract
A10: Join_Date | B10: Date employee joined the company (YYYY-MM-DD)
A11: Age | B11: Employee age in years as of current year
A12: Education | B12: Highest qualification: High School | Diploma | Bachelor | Master | PhD
A13: Region | B13: Office/base region across Indonesia
A14: Salary | B14: Monthly gross salary in IDR (Indonesian Rupiah)
... A17: Status | B17: Active = current employee | Inactive = resigned/terminated
